<?xml version="1.0" encoding="utf-8" ?>
<robot name="robot_arm_urdf">
    <link name="world" />
    <joint name="base_joint" type="fixed">
        <parent link="world" />
        <child link="base_link" />
        <origin rpy="0 0 0" xyz="0.0 0.0 0.17" />
    </joint>
    <link name="base_link">
        <inertial>
            <origin xyz="0.095642 0.17665 0.3015" rpy="0 0 0" />
            <mass value="17.147" />
            <inertia ixx="0.192" ixy="1.5581E-17" ixz="4.9423E-10" iyy="0.29544" iyz="-6.673E-18" izz="0.192" />
        </inertial>
        <visual>
            <origin xyz="0 0 0" rpy="0 0 0" />
            <geometry>
                <mesh filename="package://robot_arm_urdf/meshes/base_link.STL" />
            </geometry>
            <material name="">
                <color rgba="0.79216 0.81961 0.93333 1" />
            </material>
        </visual>
        <collision>
            <origin xyz="0 0 0" rpy="0 0 0" />
            <geometry>
                <mesh filename="package://robot_arm_urdf/meshes/base_link.STL" />
            </geometry>
        </collision>
    </link>
    <link name="link_1">
        <inertial>
            <origin xyz="-2.5702E-14 0.11047 -7.8988E-11" rpy="0 0 0" />
            <mass value="3.0905" />
            <inertia ixx="0.026302" ixy="-2.5281E-15" ixz="-1.4177E-12" iyy="0.019632" iyz="-7.4535E-12" izz="0.025388" />
        </inertial>
        <visual>
            <origin xyz="0 0 0" rpy="0 0 0" />
            <geometry>
                <mesh filename="package://robot_arm_urdf/meshes/link_1.STL" />
            </geometry>
            <material name="">
                <color rgba="1 1 1 1" />
            </material>
        </visual>
        <collision>
            <origin xyz="0 0 0" rpy="0 0 0" />
            <geometry>
                <mesh filename="package://robot_arm_urdf/meshes/link_1.STL" />
            </geometry>
        </collision>
    </link>
    <joint name="joint_1" type="revolute">
        <origin xyz="0.095642 -0.3015 0.30277" rpy="1.5708 0 0" />
        <parent link="base_link" />
        <child link="link_1" />
        <axis xyz="0 1 0" />
        <limit lower="0" upper="6.284" effort="300" velocity="3" />
    </joint>
    <link name="link_2">
        <inertial>
            <origin xyz="0 0.16752 1.1102E-16" rpy="0 0 0" />
            <mass value="5.5867" />
            <inertia ixx="0.12632" ixy="1.6467E-18" ixz="2.2412E-19" iyy="0.011401" iyz="3.5887E-18" izz="0.12911" />
        </inertial>
        <visual>
            <origin xyz="0 0 0" rpy="0 0 0" />
            <geometry>
                <mesh filename="package://robot_arm_urdf/meshes/link_2.STL" />
            </geometry>
            <material name="">
                <color rgba="0.79216 0.81961 0.93333 1" />
            </material>
        </visual>
        <collision>
            <origin xyz="0 0 0" rpy="0 0 0" />
            <geometry>
                <mesh filename="package://robot_arm_urdf/meshes/link_2.STL" />
            </geometry>
        </collision>
    </link>
    <joint name="joint_2" type="revolute">
        <origin xyz="0 0.205 0" rpy="0 0 0" />
        <parent link="link_1" />
        <child link="link_2" />
        <axis xyz="0 0 1" />
        <limit lower="-1.57" upper="1.57" effort="200" velocity="3" />
    </joint>
    <link name="link_3">
        <inertial>
            <origin xyz="-0.17893 0 -5.5511E-17" rpy="0 0 0" />
            <mass value="2.8262" />
            <inertia ixx="0.0074041" ixy="-7.9897E-18" ixz="4.0357E-17" iyy="0.028552" iyz="-3.4736E-10" izz="0.025128" />
        </inertial>
        <visual>
            <origin xyz="0 0 0" rpy="0 0 0" />
            <geometry>
                <mesh filename="package://robot_arm_urdf/meshes/link_3.STL" />
            </geometry>
            <material name="">
                <color rgba="0.79216 0.81961 0.93333 1" />
            </material>
        </visual>
        <collision>
            <origin xyz="0 0 0" rpy="0 0 0" />
            <geometry>
                <mesh filename="package://robot_arm_urdf/meshes/link_3.STL" />
            </geometry>
        </collision>
    </link>
    <joint name="joint_3" type="revolute">
        <origin xyz="0 0.4 0" rpy="0 0 0" />
        <parent link="link_2" />
        <child link="link_3" />
        <axis xyz="0 0 1" />
        <limit lower="-3.142" upper="0" effort="200" velocity="3" />
    </joint>
    <link name="link_4">
        <inertial>
            <origin xyz="-0.051672 -5.5511E-17 1.1102E-16" rpy="0 0 0" />
            <mass value="1.8097" />
            <inertia ixx="0.0023112" ixy="-5.8036E-18" ixz="-3.6586E-19" iyy="0.0096102" iyz="-5.4118E-19" izz="0.0093908" />
        </inertial>
        <visual>
            <origin xyz="0 0 0" rpy="0 0 0" />
            <geometry>
                <mesh filename="package://robot_arm_urdf/meshes/link_4.STL" />
            </geometry>
            <material name="">
                <color rgba="0.79216 0.81961 0.93333 1" />
            </material>
        </visual>
        <collision>
            <origin xyz="0 0 0" rpy="0 0 0" />
            <geometry>
                <mesh filename="package://robot_arm_urdf/meshes/link_4.STL" />
            </geometry>
        </collision>
    </link>
    <joint name="joint_4" type="revolute">
        <origin xyz="-0.35 0 0" rpy="0 0 1.5708" />
        <parent link="link_3" />
        <child link="link_4" />
        <axis xyz="0 0 1" />
        <limit lower="-3.142" upper="0" effort="200" velocity="3" />
    </joint>
    <link name="link_5">
        <inertial>
            <origin xyz="-0.018544 0 0" rpy="0 0 0" />
            <mass value="0.19053" />
            <inertia ixx="0.00030197" ixy="2.3502E-20" ixz="-3.9613E-20" iyy="0.00022817" iyz="-1.9664E-11" izz="0.00011843" />
        </inertial>
        <visual>
            <origin xyz="0 0 0" rpy="0 0 0" />
            <geometry>
                <mesh filename="package://robot_arm_urdf/meshes/link_5.STL" />
            </geometry>
            <material name="">
                <color rgba="0.79216 0.81961 0.93333 1" />
            </material>
        </visual>
        <collision>
            <origin xyz="0 0 0" rpy="0 0 0" />
            <geometry>
                <mesh filename="package://robot_arm_urdf/meshes/link_5.STL" />
            </geometry>
        </collision>
    </link>
    <joint name="joint_5" type="revolute">
        <origin xyz="-0.188 0 0" rpy="0 0 0" />
        <parent link="link_4" />
        <child link="link_5" />
        <axis xyz="1 0 0" />
        <limit lower="0" upper="3.142" effort="200" velocity="3" />
    </joint>
    <link name="link_6">
        <inertial>
            <origin xyz="-0.60237 0.4 -0.016013" rpy="0 0 0" />
            <mass value="0.11653" />
            <inertia ixx="3.9246E-05" ixy="1.0455E-19" ixz="1.0258E-05" iyy="7.1189E-05" iyz="6.1565E-21" izz="8.4875E-05" />
        </inertial>
        <visual>
            <origin xyz="0 0 0" rpy="0 0 0" />
            <geometry>
                <mesh filename="package://robot_arm_urdf/meshes/link_6.STL" />
            </geometry>
            <material name="">
                <color rgba="0.79216 0.81961 0.93333 1" />
            </material>
        </visual>
        <collision>
            <origin xyz="0 0 0" rpy="0 0 0" />
            <geometry>
                <mesh filename="package://robot_arm_urdf/meshes/link_6.STL" />
            </geometry>
        </collision>
    </link>
    <joint name="joint_6" type="prismatic">
        <origin xyz="0.54 -0.4 0" rpy="0 0 0" />
        <parent link="link_5" />
        <child link="link_6" />
        <axis xyz="0 0 -1" />
        <limit lower="0" upper="0.03" effort="100" velocity="3" />
    </joint>
    <link name="link_7">
        <inertial>
            <origin xyz="-0.60237 0.4 -0.016013" rpy="0 0 0" />
            <mass value="0.11653" />
            <inertia ixx="3.9246E-05" ixy="-1.6817E-19" ixz="1.0258E-05" iyy="7.1189E-05" iyz="-6.4938E-20" izz="8.4875E-05" />
        </inertial>
        <visual>
            <origin xyz="0 0 0" rpy="0 0 0" />
            <geometry>
                <mesh filename="package://robot_arm_urdf/meshes/link_7.STL" />
            </geometry>
            <material name="">
                <color rgba="0.79216 0.81961 0.93333 1" />
            </material>
        </visual>
        <collision>
            <origin xyz="0 0 0" rpy="0 0 0" />
            <geometry>
                <mesh filename="package://robot_arm_urdf/meshes/link_7.STL" />
            </geometry>
        </collision>
    </link>
    <joint name="joint_7" type="prismatic">
        <origin xyz="0.54 0.4 0" rpy="3.1416 0 0" />
        <parent link="link_5" />
        <child link="link_7" />
        <axis xyz="0 0 1" />
        <limit lower="-0.03" upper="0" effort="100" velocity="3" />
    </joint>
    <transmission name="link_1_trans">
        <type>transmission_interface/SimpleTransmission</type>
        <joint name="joint_1">
            <hardwareInterface>hardware_interface/PositionJointInterface</hardwareInterface>
        </joint>
        <actuator name="link_1_motor">
            <hardwareInterface>hardware_interface/PositionJointInterface</hardwareInterface>
            <mechanicalReduction>1</mechanicalReduction>
        </actuator>
    </transmission>
    <transmission name="link_2_trans">
        <type>transmission_interface/SimpleTransmission</type>
        <joint name="joint_2">
            <hardwareInterface>hardware_interface/PositionJointInterface</hardwareInterface>
        </joint>
        <actuator name="link_2_motor">
            <hardwareInterface>hardware_interface/PositionJointInterface</hardwareInterface>
            <mechanicalReduction>1</mechanicalReduction>
        </actuator>
    </transmission>
    <transmission name="link_3_trans">
        <type>transmission_interface/SimpleTransmission</type>
        <joint name="joint_3">
            <hardwareInterface>hardware_interface/PositionJointInterface</hardwareInterface>
        </joint>
        <actuator name="link_3_motor">
            <hardwareInterface>hardware_interface/PositionJointInterface</hardwareInterface>
            <mechanicalReduction>1</mechanicalReduction>
        </actuator>
    </transmission>
    <transmission name="link_4_trans">
        <type>transmission_interface/SimpleTransmission</type>
        <joint name="joint_4">
            <hardwareInterface>hardware_interface/PositionJointInterface</hardwareInterface>
        </joint>
        <actuator name="link_4_motor">
            <hardwareInterface>hardware_interface/PositionJointInterface</hardwareInterface>
            <mechanicalReduction>1</mechanicalReduction>
        </actuator>
    </transmission>
    <transmission name="link_5_trans">
        <type>transmission_interface/SimpleTransmission</type>
        <joint name="joint_5">
            <hardwareInterface>hardware_interface/PositionJointInterface</hardwareInterface>
        </joint>
        <actuator name="link_5_motor">
            <hardwareInterface>hardware_interface/PositionJointInterface</hardwareInterface>
            <mechanicalReduction>1</mechanicalReduction>
        </actuator>
    </transmission>
    <transmission name="link_6_trans">
        <type>transmission_interface/SimpleTransmission</type>
        <joint name="joint_6">
            <hardwareInterface>hardware_interface/PositionJointInterface</hardwareInterface>
        </joint>
        <actuator name="link_6_motor">
            <hardwareInterface>hardware_interface/PositionJointInterface</hardwareInterface>
            <mechanicalReduction>1</mechanicalReduction>
        </actuator>
    </transmission>
    <transmission name="link_7_trans">
        <type>transmission_interface/SimpleTransmission</type>
        <joint name="joint_7">
            <hardwareInterface>hardware_interface/PositionJointInterface</hardwareInterface>
        </joint>
        <actuator name="link_7_motor">
            <hardwareInterface>hardware_interface/PositionJointInterface</hardwareInterface>
            <mechanicalReduction>1</mechanicalReduction>
        </actuator>
    </transmission>
    <gazebo>
        <plugin name="control" filename="libgazebo_ros_control.so">
            <robotNamespace>/</robotNamespace>
        </plugin>
        <plugin name="gazebo_ros_control" filename="libgazebo_ros_control.so">
            <robotNamespace>/</robotNamespace>
        </plugin>
    </gazebo>
    <gazebo reference="link_1">
        <selfCollide>true</selfCollide>
    </gazebo>
    <gazebo reference="link_2">
        <selfCollide>true</selfCollide>
    </gazebo>
    <gazebo reference="link_3">
        <selfCollide>true</selfCollide>
    </gazebo>
    <gazebo reference="link_4">
        <selfCollide>true</selfCollide>
    </gazebo>
    <gazebo reference="link_5">
        <selfCollide>true</selfCollide>
    </gazebo>
    <gazebo reference="link_6">
        <selfCollide>true</selfCollide>
    </gazebo>
    <gazebo reference="link_7">
        <selfCollide>true</selfCollide>
    </gazebo>
</robot>

