<?xml version="1.0" encoding="utf-8"?>
<!-- This URDF was automatically created by SolidWorks to URDF Exporter! Originally created by Stephen Brawner (brawner@gmail.com) 
     Commit Version: 1.6.0-4-g7f85cfe  Build Version: 1.6.7995.38578
     For more information, please see http://wiki.ros.org/sw_urdf_exporter -->
<robot
  name="robot_description">
  <link
    name="base_link">
    <inertial>
      <origin
        xyz="-1.3908E-06 0.025233 0.091315"
        rpy="0 0 0" />
      <mass
        value="6.3881" />
      <inertia
        ixx="0.044253"
        ixy="5.7312E-07"
        ixz="6.0286E-07"
        iyy="0.032681"
        iyz="-0.002067"
        izz="0.042843" />
    </inertial>
    <visual>
      <origin
        xyz="0 0 0"
        rpy="0 0 0" />
      <geometry>
        <mesh
          filename="package://robot_description/meshes/base_link.STL" />
      </geometry>
      <material
        name="">
        <color
          rgba="0.65098 0.61961 0.58824 1" />
      </material>
    </visual>
    <collision>
      <origin
        xyz="0 0 0"
        rpy="0 0 0" />
      <geometry>
        <mesh
          filename="package://robot_description/meshes/base_link.STL" />
      </geometry>
    </collision>
  </link>
  <link
    name="link_1">
    <inertial>
      <origin
        xyz="-0.045911 0.014889 0.10379"
        rpy="0 0 0" />
      <mass
        value="6.1423" />
      <inertia
        ixx="0.016194"
        ixy="-4.2666E-05"
        ixz="0.0044536"
        iyy="0.030171"
        iyz="6.9893E-07"
        izz="0.024485" />
    </inertial>
    <visual>
      <origin
        xyz="0 0 0"
        rpy="0 0 0" />
      <geometry>
        <mesh
          filename="package://robot_description/meshes/link_1.STL" />
      </geometry>
      <material
        name="">
        <color
          rgba="0.79216 0.81961 0.93333 1" />
      </material>
    </visual>
    <collision>
      <origin
        xyz="0 0 0"
        rpy="0 0 0" />
      <geometry>
        <mesh
          filename="package://robot_description/meshes/link_1.STL" />
      </geometry>
    </collision>
  </link>
  <joint
    name="joint_1"
    type="revolute">
    <origin
      xyz="0 0 0.175"
      rpy="0 0 1.5708" />
    <parent
      link="base_link" />
    <child
      link="link_1" />
    <axis
      xyz="0 0 0" />
    <limit
      lower="0"
      upper="3.142"
      effort="300"
      velocity="3" />
  </joint>
  <link
    name="link_2">
    <inertial>
      <origin
        xyz="-4.83571810450112E-05 -0.174307508002041 -0.0349243341599044"
        rpy="0 0 0" />
      <mass
        value="2.48281663590646" />
      <inertia
        ixx="0.0497833412473321"
        ixy="-3.79326942590701E-06"
        ixz="3.91992586527837E-07"
        iyy="0.00261360494525241"
        iyz="-1.61774302029982E-05"
        izz="0.0517380702077168" />
    </inertial>
    <visual>
      <origin
        xyz="0 0 0"
        rpy="0 0 0" />
      <geometry>
        <mesh
          filename="package://robot_description/meshes/link_2.STL" />
      </geometry>
      <material
        name="">
        <color
          rgba="0.792156862745098 0.819607843137255 0.933333333333333 1" />
      </material>
    </visual>
    <collision>
      <origin
        xyz="0 0 0"
        rpy="0 0 0" />
      <geometry>
        <mesh
          filename="package://robot_description/meshes/link_2.STL" />
      </geometry>
    </collision>
  </link>
  <joint
    name="joint_2"
    type="revolute">
    <origin
      xyz="-0.089983 -0.09 0.12047"
      rpy="-1.5708 0 0" />
    <parent
      link="link_1" />
    <child
      link="link_2" />
    <axis
      xyz="0 0 -1" />
    <limit
      lower="-1.52"
      upper="1.52"
      effort="200"
      velocity="3" />
  </joint>
  <link
    name="link_3">
    <inertial>
      <origin
        xyz="0.037320223301333 -0.027141323498415 0.103036752175439"
        rpy="0 0 0" />
      <mass
        value="7.02290373419681" />
      <inertia
        ixx="0.0216860618757671"
        ixy="0.000112620386395565"
        ixz="-3.92750122540952E-05"
        iyy="0.0323021842810355"
        iyz="-2.06323348968285E-05"
        izz="0.0417729642510371" />
    </inertial>
    <visual>
      <origin
        xyz="0 0 0"
        rpy="0 0 0" />
      <geometry>
        <mesh
          filename="package://robot_description/meshes/link_3.STL" />
      </geometry>
      <material
        name="">
        <color
          rgba="0.792156862745098 0.819607843137255 0.933333333333333 1" />
      </material>
    </visual>
    <collision>
      <origin
        xyz="0 0 0"
        rpy="0 0 0" />
      <geometry>
        <mesh
          filename="package://robot_description/meshes/link_3.STL" />
      </geometry>
    </collision>
  </link>
  <joint
    name="joint_3"
    type="revolute">
    <origin
      xyz="0 -0.34998 0"
      rpy="0 0 0" />
    <parent
      link="link_2" />
    <child
      link="link_3" />
    <axis
      xyz="0 0 -1" />
    <limit
      lower="-3.142"
      upper="0"
      effort="200"
      velocity="3" />
  </joint>
  <link
    name="link_4">
    <inertial>
      <origin
        xyz="-4.16993897194295E-05 -0.0034617894273514 0.109572414245508"
        rpy="0 0 0" />
      <mass
        value="1.75839958141945" />
      <inertia
        ixx="0.0123895257712281"
        ixy="1.78342945354325E-05"
        ixz="-0.00034108838476017"
        iyy="0.0113465000523975"
        iyz="0.00018561564619931"
        izz="0.0027144775181128" />
    </inertial>
    <visual>
      <origin
        xyz="0 0 0"
        rpy="0 0 0" />
      <geometry>
        <mesh
          filename="package://robot_description/meshes/link_4.STL" />
      </geometry>
      <material
        name="">
        <color
          rgba="0.792156862745098 0.819607843137255 0.933333333333333 1" />
      </material>
    </visual>
    <collision>
      <origin
        xyz="0 0 0"
        rpy="0 0 0" />
      <geometry>
        <mesh
          filename="package://robot_description/meshes/link_4.STL" />
      </geometry>
    </collision>
  </link>
  <joint
    name="joint_4"
    type="revolute">
    <origin
      xyz="-0.078935 -0.11074 0.09"
      rpy="1.5708 0 -1.3286" />
    <parent
      link="link_3" />
    <child
      link="link_4" />
    <axis
      xyz="0 0 1" />
    <limit
      lower="0"
      upper="3.142"
      effort="200"
      velocity="3" />
  </joint>
  <link
    name="link_5">
    <inertial>
      <origin
        xyz="-0.043495 0.0093292 0.03"
        rpy="0 0 0" />
      <mass
        value="0.76569" />
      <inertia
        ixx="0.00075084"
        ixy="1.9418E-05"
        ixz="-7.8289E-07"
        iyy="0.00091618"
        iyz="-3.1686E-06"
        izz="0.00098614" />
    </inertial>
    <visual>
      <origin
        xyz="0 0 0"
        rpy="0 0 0" />
      <geometry>
        <mesh
          filename="package://robot_description/meshes/link_5.STL" />
      </geometry>
      <material
        name="">
        <color
          rgba="0.77647 0.75686 0.73725 1" />
      </material>
    </visual>
    <collision>
      <origin
        xyz="0 0 0"
        rpy="0 0 0" />
      <geometry>
        <mesh
          filename="package://robot_description/meshes/link_5.STL" />
      </geometry>
    </collision>
  </link>
  <joint
    name="joint_5"
    type="revolute">
    <origin
      xyz="0.0015915 0.029738 0.22152"
      rpy="1.5708 1.3286 0" />
    <parent
      link="link_4" />
    <child
      link="link_5" />
    <axis
      xyz="0 0 1" />
    <limit
      lower="-3.142"
      upper="0"
      effort="200"
      velocity="3" />
  </joint>
  <link
    name="link_6">
    <inertial>
      <origin
        xyz="0.025761 -0.023526 0.017713"
        rpy="0 0 0" />
      <mass
        value="0.045658" />
      <inertia
        ixx="2.5682E-05"
        ixy="-1.223E-05"
        ixz="6.686E-06"
        iyy="2.8506E-05"
        iyz="7.5054E-06"
        izz="4.0486E-05" />
    </inertial>
    <visual>
      <origin
        xyz="0 0 0"
        rpy="0 0 0" />
      <geometry>
        <mesh
          filename="package://robot_description/meshes/link_6.STL" />
      </geometry>
      <material
        name="">
        <color
          rgba="0.65098 0.61961 0.58824 1" />
      </material>
    </visual>
    <collision>
      <origin
        xyz="0 0 0"
        rpy="0 0 0" />
      <geometry>
        <mesh
          filename="package://robot_description/meshes/link_6.STL" />
      </geometry>
    </collision>
  </link>
  <joint
    name="joint_6"
    type="prismatic">
    <origin
      xyz="-0.13597 0.054196 0.03"
      rpy="-1.5708 0 3.1416" />
    <parent
      link="link_5" />
    <child
      link="link_6" />
    <axis
      xyz="0 -1 0" />
    <limit
      lower="-0.04"
      upper="0"
      effort="200"
      velocity="3" />
  </joint>
  <link
    name="link_7">
    <inertial>
      <origin
        xyz="0.0241418501748516 0.0286064426028703 0.0111598891414371"
        rpy="0 0 0" />
      <mass
        value="0.0456580141078622" />
      <inertia
        ixx="2.33821169373113E-05"
        ixy="1.43181503571547E-05"
        ixz="2.31557837472947E-06"
        iyy="2.85060531019455E-05"
        iyz="9.45921634866665E-07"
        izz="4.27863414665982E-05" />
    </inertial>
    <visual>
      <origin
        xyz="0 0 0"
        rpy="0 0 0" />
      <geometry>
        <mesh
          filename="package://robot_description/meshes/link_7.STL" />
      </geometry>
      <material
        name="">
        <color
          rgba="0.792156862745098 0.819607843137255 0.933333333333333 1" />
      </material>
    </visual>
    <collision>
      <origin
        xyz="0 0 0"
        rpy="0 0 0" />
      <geometry>
        <mesh
          filename="package://robot_description/meshes/link_7.STL" />
      </geometry>
    </collision>
  </link>
  <joint
    name="joint_7"
    type="prismatic">
    <origin
      xyz="-0.13597 0.054196 0.03"
      rpy="-1.5708 0 3.1416" />
    <parent
      link="link_5" />
    <child
      link="link_7" />
    <axis
      xyz="0 -1 0" />
    <limit
      lower="0"
      upper="0.04"
      effort="200"
      velocity="3" />
  </joint>
</robot>