<?xml version="1.0" encoding="utf-8"?>
<!-- This URDF was automatically created by SolidWorks to URDF Exporter! Originally created by Stephen Brawner (brawner@gmail.com) 
     Commit Version: 1.6.0-4-g7f85cfe  Build Version: 1.6.7995.38578
     For more information, please see http://wiki.ros.org/sw_urdf_exporter -->
<robot
  name="movable step 5.SLDASM">
  <link
    name="base_link">
    <inertial>
      <origin
        xyz="0.09345 0.1132 0.23453"
        rpy="0 0 0" />
      <mass
        value="6.3881" />
      <inertia
        ixx="0.032681"
        ixy="-0.002067"
        ixz="5.7312E-07"
        iyy="0.042843"
        iyz="6.0286E-07"
        izz="0.044253" />
    </inertial>
    <visual>
      <origin
        xyz="0 0 0"
        rpy="0 0 0" />
      <geometry>
        <mesh
          filename="package://movable step 5.SLDASM/meshes/base_link.STL" />
      </geometry>
      <material
        name="">
        <color
          rgba="0.65098 0.61961 0.58824 1" />
      </material>
    </visual>
    <collision>
      <origin
        xyz="0 0 0"
        rpy="0 0 0" />
      <geometry>
        <mesh
          filename="package://movable step 5.SLDASM/meshes/base_link.STL" />
      </geometry>
    </collision>
  </link>
  <link
    name="link_1">
    <inertial>
      <origin
        xyz="-0.045911 -0.032765 -0.014889"
        rpy="0 0 0" />
      <mass
        value="6.1423" />
      <inertia
        ixx="0.016194"
        ixy="0.0044536"
        ixz="4.2666E-05"
        iyy="0.024485"
        iyz="-6.9893E-07"
        izz="0.030171" />
    </inertial>
    <visual>
      <origin
        xyz="0 0 0"
        rpy="0 0 0" />
      <geometry>
        <mesh
          filename="package://movable step 5.SLDASM/meshes/link_1.STL" />
      </geometry>
      <material
        name="">
        <color
          rgba="0.65098 0.61961 0.58824 1" />
      </material>
    </visual>
    <collision>
      <origin
        xyz="0 0 0"
        rpy="0 0 0" />
      <geometry>
        <mesh
          filename="package://movable step 5.SLDASM/meshes/link_1.STL" />
      </geometry>
    </collision>
  </link>
  <joint
    name="joint_1"
    type="revolute">
    <origin
      xyz="0.068217 -0.23453 0.33344"
      rpy="1.5708 0 0" />
    <parent
      link="base_link" />
    <child
      link="link_1" />
    <axis
      xyz="0 0 0" />
    <limit
      lower="0"
      upper="3.142"
      effort="300"
      velocity="3" />
  </joint>
  <link
    name="link_2">
    <inertial>
      <origin
        xyz="0.15453 -0.00041643 0.12231"
        rpy="0 0 0" />
      <mass
        value="2.4828" />
      <inertia
        ixx="0.0026179"
        ixy="-2.4043E-06"
        ixz="-0.00046024"
        iyy="0.049783"
        iyz="-6.298E-06"
        izz="0.051734" />
    </inertial>
    <visual>
      <origin
        xyz="0 0 0"
        rpy="0 0 0" />
      <geometry>
        <mesh
          filename="package://movable step 5.SLDASM/meshes/link_2.STL" />
      </geometry>
      <material
        name="">
        <color
          rgba="0.79216 0.81961 0.93333 1" />
      </material>
    </visual>
    <collision>
      <origin
        xyz="0 0 0"
        rpy="0 0 0" />
      <geometry>
        <mesh
          filename="package://movable step 5.SLDASM/meshes/link_2.STL" />
      </geometry>
    </collision>
  </link>
  <joint
    name="joint_2"
    type="revolute">
    <origin
      xyz="-0.089983 0.31394 0.0041147"
      rpy="-0.0030093 0.0096985 -1.5708" />
    <parent
      link="link_1" />
    <child
      link="link_2" />
    <axis
      xyz="0 0 0" />
    <limit
      lower="-1.57"
      upper="1.57"
      effort="200"
      velocity="3" />
  </joint>
  <link
    name="link_3">
    <inertial>
      <origin
        xyz="-0.052519 0.32111 -0.013571"
        rpy="0 0 0" />
      <mass
        value="7.0229" />
      <inertia
        ixx="0.021687"
        ixy="-0.00010429"
        ixz="-0.00016471"
        iyy="0.032302"
        iyz="-2.1722E-05"
        izz="0.041772" />
    </inertial>
    <visual>
      <origin
        xyz="0 0 0"
        rpy="0 0 0" />
      <geometry>
        <mesh
          filename="package://movable step 5.SLDASM/meshes/link_3.STL" />
      </geometry>
      <material
        name="">
        <color
          rgba="0.79216 0.81961 0.93333 1" />
      </material>
    </visual>
    <collision>
      <origin
        xyz="0 0 0"
        rpy="0 0 0" />
      <geometry>
        <mesh
          filename="package://movable step 5.SLDASM/meshes/link_3.STL" />
      </geometry>
    </collision>
  </link>
  <joint
    name="joint_3"
    type="revolute">
    <origin
      xyz="0.27399 0.090224 -0.001186"
      rpy="-0.009701 0.0071523 1.5715" />
    <parent
      link="link_2" />
    <child
      link="link_3" />
    <axis
      xyz="0 0 0" />
    <limit
      lower="0"
      upper="3.142"
      effort="200"
      velocity="3" />
  </joint>
  <link
    name="link_4">
    <inertial>
      <origin
        xyz="-0.0059649 0.096397 0.0031997"
        rpy="0 0 0" />
      <mass
        value="1.7584" />
      <inertia
        ixx="0.0027145"
        ixy="0.00034109"
        ixz="0.00018562"
        iyy="0.01239"
        iyz="-1.7834E-05"
        izz="0.011347" />
    </inertial>
    <visual>
      <origin
        xyz="0 0 0"
        rpy="0 0 0" />
      <geometry>
        <mesh
          filename="package://movable step 5.SLDASM/meshes/link_4.STL" />
      </geometry>
      <material
        name="">
        <color
          rgba="0.79216 0.81961 0.93333 1" />
      </material>
    </visual>
    <collision>
      <origin
        xyz="0 0 0"
        rpy="0 0 0" />
      <geometry>
        <mesh
          filename="package://movable step 5.SLDASM/meshes/link_4.STL" />
      </geometry>
    </collision>
  </link>
  <joint
    name="joint_4"
    type="revolute">
    <origin
      xyz="-0.2926 0.33613 -0.0027093"
      rpy="0.0024433 -0.0098563 -0.243" />
    <parent
      link="link_3" />
    <child
      link="link_4" />
    <axis
      xyz="0 0 0" />
    <limit
      lower="0"
      upper="-3.142"
      effort="200"
      velocity="3" />
  </joint>
  <link
    name="link_5">
    <inertial>
      <origin
        xyz="-0.22024 0.074495 -4.2359E-10"
        rpy="0 0 0" />
      <mass
        value="0.76569" />
      <inertia
        ixx="0.00075131"
        ixy="-2.1319E-05"
        ixz="7.688E-12"
        iyy="0.00091571"
        iyz="3.2639E-06"
        izz="0.00098614" />
    </inertial>
    <visual>
      <origin
        xyz="0 0 0"
        rpy="0 0 0" />
      <geometry>
        <mesh
          filename="package://movable step 5.SLDASM/meshes/link_5.STL" />
      </geometry>
      <material
        name="">
        <color
          rgba="0.77647 0.75686 0.73725 1" />
      </material>
    </visual>
    <collision>
      <origin
        xyz="0 0 0"
        rpy="0 0 0" />
      <geometry>
        <mesh
          filename="package://movable step 5.SLDASM/meshes/link_5.STL" />
      </geometry>
    </collision>
  </link>
  <joint
    name="joint_5"
    type="revolute">
    <origin
      xyz="-0.38261 0.17115 0"
      rpy="0 0 3.1416" />
    <parent
      link="link_4" />
    <child
      link="link_5" />
    <axis
      xyz="0 0 0" />
    <limit
      lower="0"
      upper="3.142"
      effort="200"
      velocity="3" />
  </joint>
  <link
    name="link_6">
    <inertial>
      <origin
        xyz="-0.94793 0.138 -0.11556"
        rpy="0 0 0" />
      <mass
        value="0.045658" />
      <inertia
        ixx="2.342E-05"
        ixy="2.4694E-06"
        ixz="-1.3673E-05"
        iyy="4.2748E-05"
        iyz="4.3527E-06"
        izz="2.8506E-05" />
    </inertial>
    <visual>
      <origin
        xyz="0 0 0"
        rpy="0 0 0" />
      <geometry>
        <mesh
          filename="package://movable step 5.SLDASM/meshes/link_6.STL" />
      </geometry>
      <material
        name="">
        <color
          rgba="0.65098 0.61961 0.58824 1" />
      </material>
    </visual>
    <collision>
      <origin
        xyz="0 0 0"
        rpy="0 0 0" />
      <geometry>
        <mesh
          filename="package://movable step 5.SLDASM/meshes/link_6.STL" />
      </geometry>
    </collision>
  </link>
  <joint
    name="joint_6"
    type="prismatic">
    <origin
      xyz="-1.0469 0.21449 0.13909"
      rpy="0 0 -3.1416" />
    <parent
      link="link_5" />
    <child
      link="link_6" />
    <axis
      xyz="0 0 0" />
    <limit
      lower="-0.04"
      upper="0"
      effort="200"
      velocity="3" />
  </joint>
  <link
    name="link_7">
    <inertial>
      <origin
        xyz="1.2861 0.48709 -1.8186"
        rpy="0 0 0" />
      <mass
        value="0.045658" />
      <inertia
        ixx="1.8653E-05"
        ixy="3.2271E-06"
        ixz="1.1831E-05"
        iyy="4.2748E-05"
        iyz="-3.8249E-06"
        izz="3.3273E-05" />
    </inertial>
    <visual>
      <origin
        xyz="0 0 0"
        rpy="0 0 0" />
      <geometry>
        <mesh
          filename="package://movable step 5.SLDASM/meshes/link_7.STL" />
      </geometry>
      <material
        name="">
        <color
          rgba="0.79216 0.81961 0.93333 1" />
      </material>
    </visual>
    <collision>
      <origin
        xyz="0 0 0"
        rpy="0 0 0" />
      <geometry>
        <mesh
          filename="package://movable step 5.SLDASM/meshes/link_7.STL" />
      </geometry>
    </collision>
  </link>
  <joint
    name="joint_7"
    type="prismatic">
    <origin
      xyz="-1.029 0.55684 -2.0525"
      rpy="3.1416 -0.18479 0" />
    <parent
      link="link_5" />
    <child
      link="link_7" />
    <axis
      xyz="0 0 0" />
    <limit
      lower="0"
      upper="0.04"
      effort="200"
      velocity="3" />
  </joint>
</robot>